<?xml version="1.0" encoding="utf-8"?>
<!-- This URDF was automatically created by SolidWorks to URDF Exporter! Originally created by Stephen Brawner (brawner@gmail.com) 
     Commit Version: 1.6.0-1-g15f4949  Build Version: 1.6.7594.29634
     For more information, please see http://wiki.ros.org/sw_urdf_exporter -->
<robot
  name="robot_prueba_2">
  <link
    name="base_car">
    <inertial>
      <origin
        xyz="-0.0006245 0.00049097 -0.0031688"
        rpy="0 0 0" />
      <mass
        value="0.45576" />
      <inertia
        ixx="0.00058942"
        ixy="-1.7857E-09"
        ixz="-1.0054E-09"
        iyy="0.00087806"
        iyz="-2.9187E-07"
        izz="0.00040358" />
    </inertial>
    <visual>
      <origin
        xyz="0 0 0"
        rpy="0 0 0" />
      <geometry>
        <mesh
          filename="package://robot_prueba_2/meshes/base_car.STL" />
      </geometry>
      <material
        name="">
        <color
          rgba="1 0 0 1" />
      </material>
    </visual>
    <collision>
      <origin
        xyz="0 0 0"
        rpy="0 0 0" />
      <geometry>
        <mesh
          filename="package://robot_prueba_2/meshes/base_car.STL" />
      </geometry>
    </collision>
  </link>
  <link
    name="wheel1_link">
    <inertial>
      <origin
        xyz="0.0076383 0 0"
        rpy="0 0 0" />
      <mass
        value="0.028764" />
      <inertia
        ixx="9.0239E-06"
        ixy="-2.5529E-23"
        ixz="1.5353E-22"
        iyy="5.0392E-06"
        iyz="-1.0588E-22"
        izz="5.0392E-06" />
    </inertial>
    <visual>
      <origin
        xyz="0 0 0"
        rpy="0 0 0" />
      <geometry>
        <mesh
          filename="package://robot_prueba_2/meshes/wheel1_link.STL" />
      </geometry>
      <material
        name="">
        <color
          rgba="0.25098 0.25098 0.25098 1" />
      </material>
    </visual>
    <collision>
      <origin
        xyz="0 0 0"
        rpy="0 0 0" />
      <geometry>
        <mesh
          filename="package://robot_prueba_2/meshes/wheel1_link.STL" />
      </geometry>
    </collision>
  </link>
  <joint
    name="wheel1_joint"
    type="continuous">
    <origin
      xyz="0.054375 -0.02266 -0.0094392"
      rpy="0.16794 0 0" />
    <parent
      link="base_car" />
    <child
      link="wheel1_link" />
    <axis
      xyz="1 0 0" />
  </joint>
  <link
    name="flag1">
    <inertial>
      <origin
        xyz="0.00091134 0 1.7347E-18"
        rpy="0 0 0" />
      <mass
        value="0.0013585" />
      <inertia
        ixx="2.8399E-07"
        ixy="-2.1238E-25"
        ixz="-9.2299E-25"
        iyy="1.4242E-07"
        iyz="3.3087E-24"
        izz="1.4242E-07" />
    </inertial>
    <visual>
      <origin
        xyz="0 0 0"
        rpy="0 0 0" />
      <geometry>
        <mesh
          filename="package://robot_prueba_2/meshes/flag1.STL" />
      </geometry>
      <material
        name="">
        <color
          rgba="1 1 1 1" />
      </material>
    </visual>
    <collision>
      <origin
        xyz="0 0 0"
        rpy="0 0 0" />
      <geometry>
        <mesh
          filename="package://robot_prueba_2/meshes/flag1.STL" />
      </geometry>
    </collision>
  </link>
  <joint
    name="flag1_joint"
    type="fixed">
    <origin
      xyz="0.015 0 0"
      rpy="0 0 0" />
    <parent
      link="wheel1_link" />
    <child
      link="flag1" />
    <axis
      xyz="0 0 0" />
  </joint>
  <link
    name="wheel2_link">
    <inertial>
      <origin
        xyz="0.0076383 0 0"
        rpy="0 0 0" />
      <mass
        value="0.028764" />
      <inertia
        ixx="9.0239E-06"
        ixy="-1.1213E-22"
        ixz="-4.4832E-23"
        iyy="5.0392E-06"
        iyz="-2.1176E-22"
        izz="5.0392E-06" />
    </inertial>
    <visual>
      <origin
        xyz="0 0 0"
        rpy="0 0 0" />
      <geometry>
        <mesh
          filename="package://robot_prueba_2/meshes/wheel2_link.STL" />
      </geometry>
      <material
        name="">
        <color
          rgba="0.25098 0.25098 0.25098 1" />
      </material>
    </visual>
    <collision>
      <origin
        xyz="0 0 0"
        rpy="0 0 0" />
      <geometry>
        <mesh
          filename="package://robot_prueba_2/meshes/wheel2_link.STL" />
      </geometry>
    </collision>
  </link>
  <joint
    name="wheel2_joint"
    type="continuous">
    <origin
      xyz="0.054375 0.04734 -0.0094392"
      rpy="0.49394 0 0" />
    <parent
      link="base_car" />
    <child
      link="wheel2_link" />
    <axis
      xyz="1 0 0" />
  </joint>
  <link
    name="flag2">
    <inertial>
      <origin
        xyz="0.00091134 0 0"
        rpy="0 0 0" />
      <mass
        value="0.0013585" />
      <inertia
        ixx="2.8399E-07"
        ixy="5.0094E-25"
        ixz="6.7923E-25"
        iyy="1.4242E-07"
        iyz="-9.9262E-24"
        izz="1.4242E-07" />
    </inertial>
    <visual>
      <origin
        xyz="0 0 0"
        rpy="0 0 0" />
      <geometry>
        <mesh
          filename="package://robot_prueba_2/meshes/flag2.STL" />
      </geometry>
      <material
        name="">
        <color
          rgba="1 1 1 1" />
      </material>
    </visual>
    <collision>
      <origin
        xyz="0 0 0"
        rpy="0 0 0" />
      <geometry>
        <mesh
          filename="package://robot_prueba_2/meshes/flag2.STL" />
      </geometry>
    </collision>
  </link>
  <joint
    name="flag2_joint"
    type="fixed">
    <origin
      xyz="0.015 0 0"
      rpy="0 0 0" />
    <parent
      link="wheel2_link" />
    <child
      link="flag2" />
    <axis
      xyz="0 0 0" />
  </joint>
  <link
    name="wheel3_link">
    <inertial>
      <origin
        xyz="0.0076383 0 0"
        rpy="0 0 0" />
      <mass
        value="0.028764" />
      <inertia
        ixx="9.0239E-06"
        ixy="1.8245E-23"
        ixz="0"
        iyy="5.0392E-06"
        iyz="0"
        izz="5.0392E-06" />
    </inertial>
    <visual>
      <origin
        xyz="0 0 0"
        rpy="0 0 0" />
      <geometry>
        <mesh
          filename="package://robot_prueba_2/meshes/wheel3_link.STL" />
      </geometry>
      <material
        name="">
        <color
          rgba="0.25098 0.25098 0.25098 1" />
      </material>
    </visual>
    <collision>
      <origin
        xyz="0 0 0"
        rpy="0 0 0" />
      <geometry>
        <mesh
          filename="package://robot_prueba_2/meshes/wheel3_link.STL" />
      </geometry>
    </collision>
  </link>
  <joint
    name="wheel3_joint"
    type="continuous">
    <origin
      xyz="-0.055625 -0.02266 -0.0094392"
      rpy="1.8227 0 -3.1416" />
    <parent
      link="base_car" />
    <child
      link="wheel3_link" />
    <axis
      xyz="1 0 0" />
  </joint>
  <link
    name="flag3">
    <inertial>
      <origin
        xyz="0.00091134 -1.7347E-18 -3.4694E-18"
        rpy="0 0 0" />
      <mass
        value="0.0013585" />
      <inertia
        ixx="2.8399E-07"
        ixy="2.0567E-25"
        ixz="5.5604E-24"
        iyy="1.4242E-07"
        iyz="-3.3087E-24"
        izz="1.4242E-07" />
    </inertial>
    <visual>
      <origin
        xyz="0 0 0"
        rpy="0 0 0" />
      <geometry>
        <mesh
          filename="package://robot_prueba_2/meshes/flag3.STL" />
      </geometry>
      <material
        name="">
        <color
          rgba="1 1 1 1" />
      </material>
    </visual>
    <collision>
      <origin
        xyz="0 0 0"
        rpy="0 0 0" />
      <geometry>
        <mesh
          filename="package://robot_prueba_2/meshes/flag3.STL" />
      </geometry>
    </collision>
  </link>
  <joint
    name="flag3_joint"
    type="fixed">
    <origin
      xyz="0.015 0 0"
      rpy="0 0 0" />
    <parent
      link="wheel3_link" />
    <child
      link="flag3" />
    <axis
      xyz="0 0 0" />
  </joint>
  <link
    name="wheel4_link">
    <inertial>
      <origin
        xyz="0.0076383 0 0"
        rpy="0 0 0" />
      <mass
        value="0.028764" />
      <inertia
        ixx="9.0239E-06"
        ixy="1.8245E-23"
        ixz="0"
        iyy="5.0392E-06"
        iyz="0"
        izz="5.0392E-06" />
    </inertial>
    <visual>
      <origin
        xyz="0 0 0"
        rpy="0 0 0" />
      <geometry>
        <mesh
          filename="package://robot_prueba_2/meshes/wheel4_link.STL" />
      </geometry>
      <material
        name="">
        <color
          rgba="0.25098 0.25098 0.25098 1" />
      </material>
    </visual>
    <collision>
      <origin
        xyz="0 0 0"
        rpy="0 0 0" />
      <geometry>
        <mesh
          filename="package://robot_prueba_2/meshes/wheel4_link.STL" />
      </geometry>
    </collision>
  </link>
  <joint
    name="wheel4_joint"
    type="continuous">
    <origin
      xyz="-0.055625 0.04734 -0.0094392"
      rpy="1.6484 0 -3.1416" />
    <parent
      link="base_car" />
    <child
      link="wheel4_link" />
    <axis
      xyz="1 0 0" />
  </joint>
  <link
    name="flag4">
    <inertial>
      <origin
        xyz="0.00091134 1.7347E-18 6.9389E-18"
        rpy="0 0 0" />
      <mass
        value="0.0013585" />
      <inertia
        ixx="2.8399E-07"
        ixy="-5.1379E-25"
        ixz="1.2628E-24"
        iyy="1.4242E-07"
        iyz="7.4446E-24"
        izz="1.4242E-07" />
    </inertial>
    <visual>
      <origin
        xyz="0 0 0"
        rpy="0 0 0" />
      <geometry>
        <mesh
          filename="package://robot_prueba_2/meshes/flag4.STL" />
      </geometry>
      <material
        name="">
        <color
          rgba="1 1 1 1" />
      </material>
    </visual>
    <collision>
      <origin
        xyz="0 0 0"
        rpy="0 0 0" />
      <geometry>
        <mesh
          filename="package://robot_prueba_2/meshes/flag4.STL" />
      </geometry>
    </collision>
  </link>
  <joint
    name="flag4_joint"
    type="fixed">
    <origin
      xyz="0.015 0 0"
      rpy="0 0 0" />
    <parent
      link="wheel4_link" />
    <child
      link="flag4" />
    <axis
      xyz="0 0 0" />
  </joint>
</robot>