<?xml version="1.0" encoding="utf-8"?>
<!-- This URDF was automatically created by SolidWorks to URDF Exporter! Originally created by Stephen Brawner (brawner@gmail.com) 
     Commit Version: 1.6.0-1-g15f4949  Build Version: 1.6.7594.29634
     For more information, please see http://wiki.ros.org/sw_urdf_exporter -->
<robot
  name="robot_prueba_3">
  <link
    name="base_car">
    <inertial>
      <origin
        xyz="0.00030715 -0.0027084 0.011218"
        rpy="0 0 0" />
      <mass
        value="0.45576" />
      <inertia
        ixx="0.00058942"
        ixy="-1.7857E-09"
        ixz="-1.0054E-09"
        iyy="0.00087806"
        iyz="-2.9187E-07"
        izz="0.00040358" />
    </inertial>
    <visual>
      <origin
        xyz="0 0 0"
        rpy="0 0 0" />
      <geometry>
        <mesh
          filename="package://robot_prueba_3/meshes/base_car.STL" />
      </geometry>
      <material
        name="">
        <color
          rgba="1 0 0 1" />
      </material>
    </visual>
    <collision>
      <origin
        xyz="0 0 0"
        rpy="0 0 0" />
      <geometry>
        <mesh
          filename="package://robot_prueba_3/meshes/base_car.STL" />
      </geometry>
    </collision>
  </link>
  <link
    name="wheel1_link">
    <inertial>
      <origin
        xyz="0.0076383 0 6.9389E-18"
        rpy="0 0 0" />
      <mass
        value="0.028764" />
      <inertia
        ixx="9.0239E-06"
        ixy="-8.1524E-24"
        ixz="4.2436E-23"
        iyy="5.0392E-06"
        iyz="0"
        izz="5.0392E-06" />
    </inertial>
    <visual>
      <origin
        xyz="0 0 0"
        rpy="0 0 0" />
      <geometry>
        <mesh
          filename="package://robot_prueba_3/meshes/wheel1_link.STL" />
      </geometry>
      <material
        name="">
        <color
          rgba="0.25098 0.25098 0.25098 1" />
      </material>
    </visual>
    <collision>
      <origin
        xyz="0 0 0"
        rpy="0 0 0" />
      <geometry>
        <mesh
          filename="package://robot_prueba_3/meshes/wheel1_link.STL" />
      </geometry>
    </collision>
  </link>
  <joint
    name="wheel1_joint"
    type="continuous">
    <origin
      xyz="0.055307 -0.037047 -0.012639"
      rpy="1.4172 0 0" />
    <parent
      link="base_car" />
    <child
      link="wheel1_link" />
    <axis
      xyz="1 0 0" />
  </joint>
  <link
    name="flag1">
    <inertial>
      <origin
        xyz="0.00091134 0 0"
        rpy="0 0 0" />
      <mass
        value="0.0013585" />
      <inertia
        ixx="2.8399E-07"
        ixy="-2.7213E-26"
        ixz="-5.6508E-25"
        iyy="1.4242E-07"
        iyz="0"
        izz="1.4242E-07" />
    </inertial>
    <visual>
      <origin
        xyz="0 0 0"
        rpy="0 0 0" />
      <geometry>
        <mesh
          filename="package://robot_prueba_3/meshes/flag1.STL" />
      </geometry>
      <material
        name="">
        <color
          rgba="1 1 1 1" />
      </material>
    </visual>
    <collision>
      <origin
        xyz="0 0 0"
        rpy="0 0 0" />
      <geometry>
        <mesh
          filename="package://robot_prueba_3/meshes/flag1.STL" />
      </geometry>
    </collision>
  </link>
  <joint
    name="flag1_joint"
    type="fixed">
    <origin
      xyz="0.015 0 0"
      rpy="0 0 0" />
    <parent
      link="wheel1_link" />
    <child
      link="flag1" />
    <axis
      xyz="0 0 0" />
  </joint>
  <link
    name="wheel2_link">
    <inertial>
      <origin
        xyz="0.0076383 0 -6.9389E-18"
        rpy="0 0 0" />
      <mass
        value="0.028764" />
      <inertia
        ixx="9.0239E-06"
        ixy="-9.6336E-25"
        ixz="1.0421E-22"
        iyy="5.0392E-06"
        iyz="5.294E-23"
        izz="5.0392E-06" />
    </inertial>
    <visual>
      <origin
        xyz="0 0 0"
        rpy="0 0 0" />
      <geometry>
        <mesh
          filename="package://robot_prueba_3/meshes/wheel2_link.STL" />
      </geometry>
      <material
        name="">
        <color
          rgba="0.25098 0.25098 0.25098 1" />
      </material>
    </visual>
    <collision>
      <origin
        xyz="0 0 0"
        rpy="0 0 0" />
      <geometry>
        <mesh
          filename="package://robot_prueba_3/meshes/wheel2_link.STL" />
      </geometry>
    </collision>
  </link>
  <joint
    name="wheel2_joint"
    type="continuous">
    <origin
      xyz="0.055307 0.032953 -0.012639"
      rpy="1.511 0 0" />
    <parent
      link="base_car" />
    <child
      link="wheel2_link" />
    <axis
      xyz="1 0 0" />
  </joint>
  <link
    name="flag2">
    <inertial>
      <origin
        xyz="0.00091134 0 -6.9389E-18"
        rpy="0 0 0" />
      <mass
        value="0.0013585" />
      <inertia
        ixx="2.8399E-07"
        ixy="-3.5406E-25"
        ixz="-3.4763E-25"
        iyy="1.4242E-07"
        iyz="1.6544E-24"
        izz="1.4242E-07" />
    </inertial>
    <visual>
      <origin
        xyz="0 0 0"
        rpy="0 0 0" />
      <geometry>
        <mesh
          filename="package://robot_prueba_3/meshes/flag2.STL" />
      </geometry>
      <material
        name="">
        <color
          rgba="1 1 1 1" />
      </material>
    </visual>
    <collision>
      <origin
        xyz="0 0 0"
        rpy="0 0 0" />
      <geometry>
        <mesh
          filename="package://robot_prueba_3/meshes/flag2.STL" />
      </geometry>
    </collision>
  </link>
  <joint
    name="flag2_joint"
    type="fixed">
    <origin
      xyz="0.015 0 0"
      rpy="0 0 0" />
    <parent
      link="wheel2_link" />
    <child
      link="flag2" />
    <axis
      xyz="0 0 0" />
  </joint>
  <link
    name="wheel3_link">
    <inertial>
      <origin
        xyz="-0.0076383 0 0"
        rpy="0 0 0" />
      <mass
        value="0.028764" />
      <inertia
        ixx="9.0239E-06"
        ixy="-8.637E-25"
        ixz="-1.1379E-22"
        iyy="5.0392E-06"
        iyz="1.3235E-23"
        izz="5.0392E-06" />
    </inertial>
    <visual>
      <origin
        xyz="0 0 0"
        rpy="0 0 0" />
      <geometry>
        <mesh
          filename="package://robot_prueba_3/meshes/wheel3_link.STL" />
      </geometry>
      <material
        name="">
        <color
          rgba="0.25098 0.25098 0.25098 1" />
      </material>
    </visual>
    <collision>
      <origin
        xyz="0 0 0"
        rpy="0 0 0" />
      <geometry>
        <mesh
          filename="package://robot_prueba_3/meshes/wheel3_link.STL" />
      </geometry>
    </collision>
  </link>
  <joint
    name="wheel3_joint"
    type="continuous">
    <origin
      xyz="-0.054693 -0.037047 -0.012639"
      rpy="1.5916 0 0" />
    <parent
      link="base_car" />
    <child
      link="wheel3_link" />
    <axis
      xyz="1 0 0" />
  </joint>
  <link
    name="flag3">
    <inertial>
      <origin
        xyz="0.00091134 -1.7347E-18 -6.9389E-18"
        rpy="0 0 0" />
      <mass
        value="0.0013585" />
      <inertia
        ixx="2.8399E-07"
        ixy="-5.3095E-25"
        ixz="-1.1788E-24"
        iyy="1.4242E-07"
        iyz="-3.5155E-24"
        izz="1.4242E-07" />
    </inertial>
    <visual>
      <origin
        xyz="0 0 0"
        rpy="0 0 0" />
      <geometry>
        <mesh
          filename="package://robot_prueba_3/meshes/flag3.STL" />
      </geometry>
      <material
        name="">
        <color
          rgba="1 1 1 1" />
      </material>
    </visual>
    <collision>
      <origin
        xyz="0 0 0"
        rpy="0 0 0" />
      <geometry>
        <mesh
          filename="package://robot_prueba_3/meshes/flag3.STL" />
      </geometry>
    </collision>
  </link>
  <joint
    name="flag3_joint"
    type="fixed">
    <origin
      xyz="-0.015 0 0"
      rpy="3.1416 0 -3.1416" />
    <parent
      link="wheel3_link" />
    <child
      link="flag3" />
    <axis
      xyz="0 0 0" />
  </joint>
  <link
    name="wheel4_link">
    <inertial>
      <origin
        xyz="-0.0076383 -1.7347E-18 -6.9389E-18"
        rpy="0 0 0" />
      <mass
        value="0.028764" />
      <inertia
        ixx="9.0239E-06"
        ixy="-1.7349E-23"
        ixz="-2.6922E-22"
        iyy="5.0392E-06"
        iyz="0"
        izz="5.0392E-06" />
    </inertial>
    <visual>
      <origin
        xyz="0 0 0"
        rpy="0 0 0" />
      <geometry>
        <mesh
          filename="package://robot_prueba_3/meshes/wheel4_link.STL" />
      </geometry>
      <material
        name="">
        <color
          rgba="0.25098 0.25098 0.25098 1" />
      </material>
    </visual>
    <collision>
      <origin
        xyz="0 0 0"
        rpy="0 0 0" />
      <geometry>
        <mesh
          filename="package://robot_prueba_3/meshes/wheel4_link.STL" />
      </geometry>
    </collision>
  </link>
  <joint
    name="wheel4_joint"
    type="continuous">
    <origin
      xyz="-0.054693 0.032953 -0.012639"
      rpy="1.6435 0 0" />
    <parent
      link="base_car" />
    <child
      link="wheel4_link" />
    <axis
      xyz="1 0 0" />
  </joint>
  <link
    name="flag4">
    <inertial>
      <origin
        xyz="0.00091134 1.7347E-18 0"
        rpy="0 0 0" />
      <mass
        value="0.0013585" />
      <inertia
        ixx="2.8399E-07"
        ixy="2.6389E-26"
        ixz="-1.987E-24"
        iyy="1.4242E-07"
        iyz="-4.9631E-24"
        izz="1.4242E-07" />
    </inertial>
    <visual>
      <origin
        xyz="0 0 0"
        rpy="0 0 0" />
      <geometry>
        <mesh
          filename="package://robot_prueba_3/meshes/flag4.STL" />
      </geometry>
      <material
        name="">
        <color
          rgba="1 1 1 1" />
      </material>
    </visual>
    <collision>
      <origin
        xyz="0 0 0"
        rpy="0 0 0" />
      <geometry>
        <mesh
          filename="package://robot_prueba_3/meshes/flag4.STL" />
      </geometry>
    </collision>
  </link>
  <joint
    name="flag4_joint"
    type="fixed">
    <origin
      xyz="-0.015 0 0"
      rpy="-3.1416 0 -3.1416" />
    <parent
      link="wheel4_link" />
    <child
      link="flag4" />
    <axis
      xyz="0 0 0" />
  </joint>
</robot>