<?xml version="1.0" encoding="utf-8"?>
<!-- This URDF was automatically created by SolidWorks to URDF Exporter! Originally created by Stephen Brawner (brawner@gmail.com) 
     Commit Version: 1.6.0-1-g15f4949  Build Version: 1.6.7594.29634
     For more information, please see http://wiki.ros.org/sw_urdf_exporter -->
<robot
  name="robot_prueba_1">
  <link
    name="base_link">
    <inertial>
      <origin
        xyz="-0.012475 -0.0070341 0.14417"
        rpy="0 0 0" />
      <mass
        value="0.45576" />
      <inertia
        ixx="0.00058942"
        ixy="-1.8006E-09"
        ixz="-1.0323E-09"
        iyy="0.00087806"
        iyz="-2.9185E-07"
        izz="0.00040358" />
    </inertial>
    <visual>
      <origin
        xyz="0 0 0"
        rpy="0 0 0" />
      <geometry>
        <mesh
          filename="package://robot_prueba_1/meshes/base_link.STL" />
      </geometry>
      <material
        name="">
        <color
          rgba="1 0 0 1" />
      </material>
    </visual>
    <collision>
      <origin
        xyz="0 0 0"
        rpy="0 0 0" />
      <geometry>
        <mesh
          filename="package://robot_prueba_1/meshes/base_link.STL" />
      </geometry>
    </collision>
  </link>
  <link
    name="wheel_1">
    <inertial>
      <origin
        xyz="0.00742343520002757 -1.38777878078145E-17 -5.55111512312578E-17"
        rpy="0 0 0" />
      <mass
        value="0.0278392236677135" />
      <inertia
        ixx="8.73797889568867E-06"
        ixy="6.52409166031564E-23"
        ixz="7.48515615271212E-23"
        iyy="4.855923813547E-06"
        iyz="-6.35274710440725E-22"
        izz="4.85592381354699E-06" />
    </inertial>
    <visual>
      <origin
        xyz="0 0 0"
        rpy="0 0 0" />
      <geometry>
        <mesh
          filename="package://robot_prueba_1/meshes/wheel_1.STL" />
      </geometry>
      <material
        name="">
        <color
          rgba="0 0 0 1" />
      </material>
    </visual>
    <collision>
      <origin
        xyz="0 0 0"
        rpy="0 0 0" />
      <geometry>
        <mesh
          filename="package://robot_prueba_1/meshes/wheel_1.STL" />
      </geometry>
    </collision>
  </link>
  <joint
    name="joint_wheel_1"
    type="continuous">
    <origin
      xyz="-0.067475 -0.17 -0.016964"
      rpy="1.8227 0 3.1416" />
    <parent
      link="base_link" />
    <child
      link="wheel_1" />
    <axis
      xyz="1 0 0" />
  </joint>
  <link
    name="wheel_2">
    <inertial>
      <origin
        xyz="0.00742343520002757 8.32667268468867E-17 -1.38777878078145E-17"
        rpy="0 0 0" />
      <mass
        value="0.0278392236677135" />
      <inertia
        ixx="8.73797889568868E-06"
        ixy="1.20957800499272E-22"
        ixz="1.0546310936981E-22"
        iyy="4.855923813547E-06"
        iyz="4.2351647362715E-22"
        izz="4.855923813547E-06" />
    </inertial>
    <visual>
      <origin
        xyz="0 0 0"
        rpy="0 0 0" />
      <geometry>
        <mesh
          filename="package://robot_prueba_1/meshes/wheel_2.STL" />
      </geometry>
      <material
        name="">
        <color
          rgba="0 0 0 1" />
      </material>
    </visual>
    <collision>
      <origin
        xyz="0 0 0"
        rpy="0 0 0" />
      <geometry>
        <mesh
          filename="package://robot_prueba_1/meshes/wheel_2.STL" />
      </geometry>
    </collision>
  </link>
  <joint
    name="joint_wheel_2"
    type="continuous">
    <origin
      xyz="0.042525 -0.17 -0.016964"
      rpy="0.49848 0 0" />
    <parent
      link="base_link" />
    <child
      link="wheel_2" />
    <axis
      xyz="1 0 0" />
  </joint>
  <link
    name="wheel_3">
    <inertial>
      <origin
        xyz="0.00742343520002757 0 0"
        rpy="0 0 0" />
      <mass
        value="0.0278392236677135" />
      <inertia
        ixx="8.73797889568867E-06"
        ixy="7.1208467720329E-23"
        ixz="-1.21942835150546E-23"
        iyy="4.855923813547E-06"
        iyz="-8.470329472543E-22"
        izz="4.85592381354699E-06" />
    </inertial>
    <visual>
      <origin
        xyz="0 0 0"
        rpy="0 0 0" />
      <geometry>
        <mesh
          filename="package://robot_prueba_1/meshes/wheel_3.STL" />
      </geometry>
      <material
        name="">
        <color
          rgba="0 0 0 1" />
      </material>
    </visual>
    <collision>
      <origin
        xyz="0 0 0"
        rpy="0 0 0" />
      <geometry>
        <mesh
          filename="package://robot_prueba_1/meshes/wheel_3.STL" />
      </geometry>
    </collision>
  </link>
  <joint
    name="joint_wheel_3"
    type="continuous">
    <origin
      xyz="-0.067475 -0.1 -0.016964"
      rpy="1.6785 0 3.1416" />
    <parent
      link="base_link" />
    <child
      link="wheel_3" />
    <axis
      xyz="1 0 0" />
  </joint>
  <link
    name="wheel_4">
    <inertial>
      <origin
        xyz="0.00742343520002757 0 0"
        rpy="0 0 0" />
      <mass
        value="0.0278392236677135" />
      <inertia
        ixx="8.73797889568866E-06"
        ixy="1.48536760717649E-22"
        ixz="-1.36509373770758E-22"
        iyy="4.85592381354699E-06"
        iyz="8.470329472543E-22"
        izz="4.85592381354699E-06" />
    </inertial>
    <visual>
      <origin
        xyz="0 0 0"
        rpy="0 0 0" />
      <geometry>
        <mesh
          filename="package://robot_prueba_1/meshes/wheel_4.STL" />
      </geometry>
      <material
        name="">
        <color
          rgba="0 0 0 1" />
      </material>
    </visual>
    <collision>
      <origin
        xyz="0 0 0"
        rpy="0 0 0" />
      <geometry>
        <mesh
          filename="package://robot_prueba_1/meshes/wheel_4.STL" />
      </geometry>
    </collision>
  </link>
  <joint
    name="joint_wheel_4"
    type="continuous">
    <origin
      xyz="0.042525 -0.1 -0.016964"
      rpy="0.49394 0 0" />
    <parent
      link="base_link" />
    <child
      link="wheel_4" />
    <axis
      xyz="1 0 0" />
  </joint>
</robot>