<?xml version="1.0" encoding="utf-8"?>
<!-- This URDF was automatically created by SolidWorks to URDF Exporter! Originally created by Stephen Brawner (brawner@gmail.com) 
     Commit Version: 1.6.0-1-g15f4949  Build Version: 1.6.7594.29634
     For more information, please see http://wiki.ros.org/sw_urdf_exporter -->
<robot
  name="project_arm_1">
  <link
    name="base_robot">
    <inertial>
      <origin
        xyz="0.087847 0.068109 0.042187"
        rpy="0 0 0" />
      <mass
        value="5.7621" />
      <inertia
        ixx="0.036816"
        ixy="-1.3844E-18"
        ixz="2.8055E-18"
        iyy="0.035512"
        iyz="2.7695E-19"
        izz="0.036816" />
    </inertial>
    <visual>
      <origin
        xyz="0 0 0"
        rpy="0 0 0" />
      <geometry>
        <mesh
          filename="package://project_arm_1/meshes/base_robot.STL" />
      </geometry>
      <material
        name="">
        <color
          rgba="0.64706 0.61961 0.58824 1" />
      </material>
    </visual>
    <collision>
      <origin
        xyz="0 0 0"
        rpy="0 0 0" />
      <geometry>
        <mesh
          filename="package://project_arm_1/meshes/base_robot.STL" />
      </geometry>
    </collision>
  </link>
  <link
    name="link_1">
    <inertial>
      <origin
        xyz="0 6.9389E-18 0.026561"
        rpy="0 0 0" />
      <mass
        value="1.9626" />
      <inertia
        ixx="0.0033715"
        ixy="1.9418E-21"
        ixz="4.9972E-20"
        iyy="0.0035217"
        iyz="-1.2708E-19"
        izz="0.0050996" />
    </inertial>
    <visual>
      <origin
        xyz="0 0 0"
        rpy="0 0 0" />
      <geometry>
        <mesh
          filename="package://project_arm_1/meshes/link_1.STL" />
      </geometry>
      <material
        name="">
        <color
          rgba="0.89804 0.91765 0.92941 1" />
      </material>
    </visual>
    <collision>
      <origin
        xyz="0 0 0"
        rpy="0 0 0" />
      <geometry>
        <mesh
          filename="package://project_arm_1/meshes/link_1.STL" />
      </geometry>
    </collision>
  </link>
  <joint
    name="joint_link_1"
    type="continuous">
    <origin
      xyz="0.087847 -0.042187 0.1015"
      rpy="0 0 0" />
    <parent
      link="base_robot" />
    <child
      link="link_1" />
    <axis
      xyz="0 0 1" />
    <limit
      lower="-1.5708"
      upper="1.5708"
      effort="0"
      velocity="0" />
  </joint>
  <link
    name="link_2">
    <inertial>
      <origin
        xyz="-0.048042 -6.9389E-18 -0.0015"
        rpy="0 0 0" />
      <mass
        value="0.77538" />
      <inertia
        ixx="0.00035874"
        ixy="-1.7326E-19"
        ixz="-3.7983E-21"
        iyy="0.0017431"
        iyz="4.4738E-21"
        izz="0.0017248" />
    </inertial>
    <visual>
      <origin
        xyz="0 0 0"
        rpy="0 0 0" />
      <geometry>
        <mesh
          filename="package://project_arm_1/meshes/link_2.STL" />
      </geometry>
      <material
        name="">
        <color
          rgba="0.89804 0.91765 0.92941 1" />
      </material>
    </visual>
    <collision>
      <origin
        xyz="0 0 0"
        rpy="0 0 0" />
      <geometry>
        <mesh
          filename="package://project_arm_1/meshes/link_2.STL" />
      </geometry>
    </collision>
  </link>
  <joint
    name="joint_link_2"
    type="continuous">
    <origin
      xyz="0 0 0.086"
      rpy="3.1416 1.5708 0" />
    <parent
      link="link_1" />
    <child
      link="link_2" />
    <axis
      xyz="0 0 1" />
    <limit
      lower="-1.5708"
      upper="1.5708"
      effort="0"
      velocity="0" />
  </joint>
  <link
    name="link_3">
    <inertial>
      <origin
        xyz="-0.053463 -6.9389E-18 -0.0015"
        rpy="0 0 0" />
      <mass
        value="0.69186" />
      <inertia
        ixx="0.00030281"
        ixy="-1.1004E-19"
        ixz="-2.672E-20"
        iyy="0.0014993"
        iyz="2.2966E-20"
        izz="0.0014926" />
    </inertial>
    <visual>
      <origin
        xyz="0 0 0"
        rpy="0 0 0" />
      <geometry>
        <mesh
          filename="package://project_arm_1/meshes/link_3.STL" />
      </geometry>
      <material
        name="">
        <color
          rgba="0.89804 0.91765 0.92941 1" />
      </material>
    </visual>
    <collision>
      <origin
        xyz="0 0 0"
        rpy="0 0 0" />
      <geometry>
        <mesh
          filename="package://project_arm_1/meshes/link_3.STL" />
      </geometry>
    </collision>
  </link>
  <joint
    name="joint_link_3"
    type="continuous">
    <origin
      xyz="-0.125 0 0"
      rpy="0 0 0" />
    <parent
      link="link_2" />
    <child
      link="link_3" />
    <axis
      xyz="0 0 1" />
    <limit
      lower="-1.5708"
      upper="1.5708"
      effort="0"
      velocity="0" />
  </joint>
  <link
    name="link_4">
    <inertial>
      <origin
        xyz="-0.041905 -2.0817E-17 -0.0015"
        rpy="0 0 0" />
      <mass
        value="0.57994" />
      <inertia
        ixx="0.00024652"
        ixy="2.9958E-20"
        ixz="-6.9768E-20"
        iyy="0.00088008"
        iyz="-2.5262E-20"
        izz="0.00097842" />
    </inertial>
    <visual>
      <origin
        xyz="0 0 0"
        rpy="0 0 0" />
      <geometry>
        <mesh
          filename="package://project_arm_1/meshes/link_4.STL" />
      </geometry>
      <material
        name="">
        <color
          rgba="0.89804 0.91765 0.92941 1" />
      </material>
    </visual>
    <collision>
      <origin
        xyz="0 0 0"
        rpy="0 0 0" />
      <geometry>
        <mesh
          filename="package://project_arm_1/meshes/link_4.STL" />
      </geometry>
    </collision>
  </link>
  <joint
    name="joint_link_4"
    type="continuous">
    <origin
      xyz="-0.125 0 0"
      rpy="0 0 0" />
    <parent
      link="link_3" />
    <child
      link="link_4" />
    <axis
      xyz="0 0 1" />
    <limit
      lower="-1.5708"
      upper="1.5708"
      effort="0"
      velocity="0" />
  </joint>
</robot>