<?xml version="1.0" encoding="utf-8"?>
<!-- This URDF was automatically created by SolidWorks to URDF Exporter! Originally created by Stephen Brawner (brawner@gmail.com) 
     Commit Version: 1.6.0-1-g15f4949  Build Version: 1.6.7594.29634
     For more information, please see http://wiki.ros.org/sw_urdf_exporter -->
<robot
  name="project_arm_1">
  <link
    name="base_robot">
    <inertial>
      <origin
        xyz="0.087847 0.068109 0.042187"
        rpy="0 0 0" />
      <mass
        value="0.72938" />
      <inertia
        ixx="0.0046602"
        ixy="-1.6837E-19"
        ixz="3.3087E-19"
        iyy="0.0044952"
        iyz="3.5672E-20"
        izz="0.0046602" />
    </inertial>
    <visual>
      <origin
        xyz="0 0 0"
        rpy="0 0 0" />
      <geometry>
        <mesh
          filename="package://project_arm_1/meshes/base_robot.STL" />
      </geometry>
      <material
        name="">
        <color
          rgba="0.79216 0.81961 0.93333 1" />
      </material>
    </visual>
    <collision>
      <origin
        xyz="0 0 0"
        rpy="0 0 0" />
      <geometry>
        <mesh
          filename="package://project_arm_1/meshes/base_robot.STL" />
      </geometry>
    </collision>
  </link>
  <link
    name="link_1">
    <inertial>
      <origin
        xyz="1.3878E-17 -1.3878E-17 0.026561"
        rpy="0 0 0" />
      <mass
        value="0.72688" />
      <inertia
        ixx="0.0010151"
        ixy="-6.2818E-06"
        ixz="1.1601E-19"
        iyy="0.0010693"
        iyz="4.8316E-20"
        izz="0.0018887" />
    </inertial>
    <visual>
      <origin
        xyz="0 0 0"
        rpy="0 0 0" />
      <geometry>
        <mesh
          filename="package://project_arm_1/meshes/link_1.STL" />
      </geometry>
      <material
        name="">
        <color
          rgba="0.79216 0.81961 0.93333 1" />
      </material>
    </visual>
    <collision>
      <origin
        xyz="0 0 0"
        rpy="0 0 0" />
      <geometry>
        <mesh
          filename="package://project_arm_1/meshes/link_1.STL" />
      </geometry>
    </collision>
  </link>
  <joint
    name="joint_link_1"
    type="continuous">
    <origin
      xyz="0.087847 -0.042187 0.1015"
      rpy="0 0 -1.9517" />
    <parent
      link="base_robot" />
    <child
      link="link_1" />
    <axis
      xyz="0 0 1" />
  </joint>
  <link
    name="link_2">
    <inertial>
      <origin
        xyz="-0.048042 -2.7756E-17 0.0015"
        rpy="0 0 0" />
      <mass
        value="0.28718" />
      <inertia
        ixx="0.00013287"
        ixy="-3.5719E-19"
        ixz="-1.3105E-19"
        iyy="0.00064561"
        iyz="-1.3553E-20"
        izz="0.00063883" />
    </inertial>
    <visual>
      <origin
        xyz="0 0 0"
        rpy="0 0 0" />
      <geometry>
        <mesh
          filename="package://project_arm_1/meshes/link_2.STL" />
      </geometry>
      <material
        name="">
        <color
          rgba="0 0.75294 0.75294 1" />
      </material>
    </visual>
    <collision>
      <origin
        xyz="0 0 0"
        rpy="0 0 0" />
      <geometry>
        <mesh
          filename="package://project_arm_1/meshes/link_2.STL" />
      </geometry>
    </collision>
  </link>
  <joint
    name="joint_link_2"
    type="continuous">
    <origin
      xyz="0 0 0.086"
      rpy="1.5708 1.5675 1.6847" />
    <parent
      link="link_1" />
    <child
      link="link_2" />
    <axis
      xyz="0 0 1" />
  </joint>
  <link
    name="link_3">
    <inertial>
      <origin
        xyz="-0.053463 2.7756E-17 0.0015"
        rpy="0 0 0" />
      <mass
        value="0.25625" />
      <inertia
        ixx="0.00011215"
        ixy="4.3536E-19"
        ixz="1.9731E-19"
        iyy="0.00055529"
        iyz="1.3553E-20"
        izz="0.0005528" />
    </inertial>
    <visual>
      <origin
        xyz="0 0 0"
        rpy="0 0 0" />
      <geometry>
        <mesh
          filename="package://project_arm_1/meshes/link_3.STL" />
      </geometry>
      <material
        name="">
        <color
          rgba="0.79216 0.81961 0.93333 1" />
      </material>
    </visual>
    <collision>
      <origin
        xyz="0 0 0"
        rpy="0 0 0" />
      <geometry>
        <mesh
          filename="package://project_arm_1/meshes/link_3.STL" />
      </geometry>
    </collision>
  </link>
  <joint
    name="joint_link_3"
    type="continuous">
    <origin
      xyz="-0.125 0 0"
      rpy="0 0 0.0082554" />
    <parent
      link="link_2" />
    <child
      link="link_3" />
    <axis
      xyz="0 0 1" />
  </joint>
  <link
    name="link_4">
    <inertial>
      <origin
        xyz="-0.041905 -5.5511E-17 0.0015"
        rpy="0 0 0" />
      <mass
        value="0.21479" />
      <inertia
        ixx="9.1304E-05"
        ixy="-2.882E-19"
        ixz="-1.0291E-19"
        iyy="0.00032596"
        iyz="2.0329E-20"
        izz="0.00036238" />
    </inertial>
    <visual>
      <origin
        xyz="0 0 0"
        rpy="0 0 0" />
      <geometry>
        <mesh
          filename="package://project_arm_1/meshes/link_4.STL" />
      </geometry>
      <material
        name="">
        <color
          rgba="0.9098 0.44314 0.031373 1" />
      </material>
    </visual>
    <collision>
      <origin
        xyz="0 0 0"
        rpy="0 0 0" />
      <geometry>
        <mesh
          filename="package://project_arm_1/meshes/link_4.STL" />
      </geometry>
    </collision>
  </link>
  <joint
    name="joint_link_4"
    type="continuous">
    <origin
      xyz="-0.125 0 0"
      rpy="0 0 -0.16949" />
    <parent
      link="link_3" />
    <child
      link="link_4" />
    <axis
      xyz="0 0 1" />
  </joint>
</robot>